Workbook

Sheet CABLE DATA (OD)
A1: TABEL DIAMETER LUAR KABEL (OUTER DIAMETER / OD)
A2: Sel kuning = INPUT. Ganti angka OD di kolom C sesuai katalog pabrikan; seluruh workbook ikut ter-update otomatis.
A3: Nilai di bawah adalah OD TIPIKAL pasaran Indonesia (Supreme/Kabelindo/Kabelmetal) - WAJIB DIVERIFIKASI ke katalog pabrikan sebelum konstruksi.
A5: KODE TIPE | B5: DESKRIPSI KABEL | C5: OD (mm) | D5: LUAS PENAMPANG (mm2) | E5: KETERANGAN
A6: 3C-4 | B6: 1x3C-4mm2 Cu/XLPE/PVC (N2XY) | C6: 13.5 | D6: =PI()/4*C6^2 -> 143.13882 | E6: Tipikal N2XY 3x4mm2
A7: 5C-4 | B7: 1x5C-4mm2 Cu/XLPE/PVC (N2XY) | C7: 16 | D7: =PI()/4*C7^2 -> 201.06193 | E7: Tipikal N2XY 5x4mm2
A8: 4C-6 | B8: 1x4C-6mm2 Cu/XLPE/PVC (N2XY) | C8: 16 | D8: =PI()/4*C8^2 -> 201.06193 | E8: Incoming DB-UTILITY (DEG)
A9: 4C-25 | B9: 1x4C-25mm2 Cu/XLPE/PVC (N2XY) | C9: 27.5 | D9: =PI()/4*C9^2 -> 593.95736 | E9: Incoming DB-HVAC UTILITY / EMERGENCY
A10: 4C-70 | B10: 1x4C-70mm2 Cu/XLPE/PVC (N2XY) | C10: 34 | D10: =PI()/4*C10^2 -> 907.92028 | E10: Incoming DB-UTILITY
A11: 1C-6 | B11: 1C-6mm2 Cu/PVC G/Y (NYA) | C11: 5.5 | D11: =PI()/4*C11^2 -> 23.758294 | E11: Pembumian DB-UTILITY (DEG)
A12: 1C-16 | B12: 1C-16mm2 Cu/PVC G/Y (NYA) | C12: 8 | D12: =PI()/4*C12^2 -> 50.265482 | E12: Pembumian DB-HVAC UTILITY / EMERGENCY
A13: 1C-35 | B13: 1C-35mm2 Cu/PVC G/Y (NYA) | C13: 11 | D13: =PI()/4*C13^2 -> 95.033178 | E13: Pembumian DB-UTILITY
A14: 2C-2.5F | B14: 1x2C-2.5mm2 Cu/MGT/XLPE/LSZH (FRC) | C14: 11 | D14: =PI()/4*C14^2 -> 95.033178 | E14: Kabel fire alarm tahan api

Sheet CABLE SCHEDULE
A1: CABLE SCHEDULE - REKAP SELURUH KABEL DARI 3 GAMBAR PANEL SCHEDULE
A2: Sumber: MEFLV6001 (DB-UTILITY & DB-UTILITY DEG), MEFLV6002 (DB-HVAC UTILITY), MEFLV6003 (DB-HVAC UTILITY EMERGENCY)
A3: Kolom OD diambil otomatis dari sheet 'CABLE DATA (OD)' dengan INDEX/MATCH. Baris FUTURE/SPARE tidak diberi OD (jumlah run = 0).
A5: NO | B5: GAMBAR | C5: PANEL | D5: CIRCUIT No. | E5: KATEGORI | F5: SUPPLY FOR SYSTEM | G5: DAYA (kW) | H5: DESKRIPSI KABEL | I5: KODE TIPE | J5: JML RUN | K5: OD (mm) | L5: LEBAR TOTAL (mm) | M5: LUAS TOTAL (mm2) | N5: CATATAN
A6: 1 | B6: MEFLV6001 | C6: DB-UTILITY | D6: FA-INTERLOCK | E6: INCOMING | F6: FIRE ALARM INTERLOCK | G6: 0 | H6: 1x2C-2.5mm2 Cu/MGT/XLPE/LSZH (FRC) | I6: 2C-2.5F | J6: 1 | K6: =INDEX(OD_NILAI,MATCH(I6,OD_KODE,0)) -> 11 | L6: =J6*K6 -> 11 | M6: =J6*PI()/4*K6^2 -> 95.033178 | N6: Interlock fire alarm - tray terpisah
A7: 2 | B7: MEFLV6001 | C7: DB-UTILITY | D7: INCOMING | E7: INCOMING | F7: FEEDER PANEL | G7: 0 | H7: 1x4C-70mm2 Cu/XLPE/PVC | I7: 4C-70 | J7: 1 | K7: =INDEX(OD_NILAI,MATCH(I7,OD_KODE,0)) -> 34 | L7: =J7*K7 -> 34 | M7: =J7*PI()/4*K7^2 -> 907.92028 | N7: Feeder utama (Pact 65.52 kW), in cable tray/trunking. Daya diisi 0 agar total kW tidak dobel dgn outgoing.
A8: 3 | B8: MEFLV6001 | C8: DB-UTILITY | D8: INCOMING-E | E8: INCOMING | F8: FEEDER PANEL | G8: 0 | H8: 1C-35mm2 Cu/PVC G/Y | I8: 1C-35 | J8: 1 | K8: =INDEX(OD_NILAI,MATCH(I8,OD_KODE,0)) -> 11 | L8: =J8*K8 -> 11 | M8: =J8*PI()/4*K8^2 -> 95.033178 | N8: Pembumian feeder utama
A9: 4 | B9: MEFLV6001 | C9: DB-UTILITY | D9: DB-UTILTY-01 | E9: OUTGOING | F9: LIGHTING (F)/1 | G9: 0.144 | H9: 1x3C-4mm2 Cu/XLPE/PVC INCLUDING (E) | I9: 3C-4 | J9: 1 | K9: =INDEX(OD_NILAI,MATCH(I9,OD_KODE,0)) -> 13.5 | L9: =J9*K9 -> 13.5 | M9: =J9*PI()/4*K9^2 -> 143.13882
A10: 5 | B10: MEFLV6001 | C10: DB-UTILITY | D10: DB-UTILTY-02 | E10: OUTGOING | F10: LIGHTING (F)/2 | G10: 2.7 | H10: 1x3C-4mm2 Cu/XLPE/PVC INCLUDING (E) | I10: 3C-4 | J10: 1 | K10: =INDEX(OD_NILAI,MATCH(I10,OD_KODE,0)) -> 13.5 | L10: =J10*K10 -> 13.5 | M10: =J10*PI()/4*K10^2 -> 143.13882
A11: 6 | B11: MEFLV6001 | C11: DB-UTILITY | D11: DB-UTILTY-03 | E11: OUTGOING | F11: LIGHTING (F)/3 | G11: 2.4 | H11: 1x3C-4mm2 Cu/XLPE/PVC INCLUDING (E) | I11: 3C-4 | J11: 1 | K11: =INDEX(OD_NILAI,MATCH(I11,OD_KODE,0)) -> 13.5 | L11: =J11*K11 -> 13.5 | M11: =J11*PI()/4*K11^2 -> 143.13882
A12: 7 | B12: MEFLV6001 | C12: DB-UTILITY | D12: DB-UTILTY-04 | E12: OUTGOING | F12: LIGHTING (F)/4 | G12: 1.35 | H12: 1x3C-4mm2 Cu/XLPE/PVC INCLUDING (E) | I12: 3C-4 | J12: 1 | K12: =INDEX(OD_NILAI,MATCH(I12,OD_KODE,0)) -> 13.5 | L12: =J12*K12 -> 13.5 | M12: =J12*PI()/4*K12^2 -> 143.13882
A13: 8 | B13: MEFLV6001 | C13: DB-UTILITY | D13: DB-UTILTY-05 | E13: OUTGOING | F13: LIGHTING (F)/5 | G13: 0.312 | H13: 1x3C-4mm2 Cu/XLPE/PVC INCLUDING (E) | I13: 3C-4 | J13: 1 | K13: =INDEX(OD_NILAI,MATCH(I13,OD_KODE,0)) -> 13.5 | L13: =J13*K13 -> 13.5 | M13: =J13*PI()/4*K13^2 -> 143.13882
A14: 9 | B14: MEFLV6001 | C14: DB-UTILITY | D14: DB-UTILTY-06 | E14: OUTGOING | F14: LIGHTING (F)/6 | G14: 0.8 | H14: 1x3C-4mm2 Cu/XLPE/PVC INCLUDING (E) | I14: 3C-4 | J14: 1 | K14: =INDEX(OD_NILAI,MATCH(I14,OD_KODE,0)) -> 13.5 | L14: =J14*K14 -> 13.5 | M14: =J14*PI()/4*K14^2 -> 143.13882
A15: 10 | B15: MEFLV6001 | C15: DB-UTILITY | D15: DB-UTILTY-07 | E15: OUTGOING | F15: EXIT LIGHTING (F)/7 | G15: 0.055 | H15: 1x3C-4mm2 Cu/XLPE/PVC INCLUDING (E) | I15: 3C-4 | J15: 1 | K15: =INDEX(OD_NILAI,MATCH(I15,OD_KODE,0)) -> 13.5 | L15: =J15*K15 -> 13.5 | M15: =J15*PI()/4*K15^2 -> 143.13882
A16: 11 | B16: MEFLV6001 | C16: DB-UTILITY | D16: DB-UTILTY-08 | E16: OUTGOING | F16: EM. LIGHTING (F)/8 | G16: 0.108 | H16: 1x3C-4mm2 Cu/XLPE/PVC INCLUDING (E) | I16: 3C-4 | J16: 1 | K16: =INDEX(OD_NILAI,MATCH(I16,OD_KODE,0)) -> 13.5 | L16: =J16*K16 -> 13.5 | M16: =J16*PI()/4*K16^2 -> 143.13882
A17: 12 | B17: MEFLV6001 | C17: DB-UTILITY | D17: DB-UTILTY-09 | E17: OUTGOING | F17: RECEPTACLE (F)/9 | G17: 0.6 | H17: 1x3C-4mm2 Cu/XLPE/PVC INCLUDING (E) | I17: 3C-4 | J17: 1 | K17: =INDEX(OD_NILAI,MATCH(I17,OD_KODE,0)) -> 13.5 | L17: =J17*K17 -> 13.5 | M17: =J17*PI()/4*K17^2 -> 143.13882
A18: 13 | B18: MEFLV6001 | C18: DB-UTILITY | D18: DB-UTILTY-10 | E18: OUTGOING | F18: RECEPTACLE (F)/10 | G18: 0.8 | H18: 1x3C-4mm2 Cu/XLPE/PVC INCLUDING (E) | I18: 3C-4 | J18: 1 | K18: =INDEX(OD_NILAI,MATCH(I18,OD_KODE,0)) -> 13.5 | L18: =J18*K18 -> 13.5 | M18: =J18*PI()/4*K18^2 -> 143.13882
A19: 14 | B19: MEFLV6001 | C19: DB-UTILITY | D19: DB-UTILTY-11 | E19: OUTGOING | F19: FOR SHUTTER DOOR (F)/11 | G19: 2.2 | H19: 1x3C-4mm2 Cu/XLPE/PVC INCLUDING (E) | I19: 3C-4 | J19: 1 | K19: =INDEX(OD_NILAI,MATCH(I19,OD_KODE,0)) -> 13.5 | L19: =J19*K19 -> 13.5 | M19: =J19*PI()/4*K19^2 -> 143.13882
A20: 15 | B20: MEFLV6001 | C20: DB-UTILITY | D20: DB-UTILTY-12 | E20: OUTGOING | F20: RECEPTACLE (F)/12,13,14 | G20: 9 | H20: 1x3C-4mm2 Cu/XLPE/PVC INCLUDING (E) | I20: 3C-4 | J20: 1 | K20: =INDEX(OD_NILAI,MATCH(I20,OD_KODE,0)) -> 13.5 | L20: =J20*K20 -> 13.5 | M20: =J20*PI()/4*K20^2 -> 143.13882
... A34: 29 | B34: MEFLV6001 | C34: DB-UTILITY | D34: DB-UTILTY-26 | E34: OUTGOING | F34: FOR SHUTTER DOOR (F)/34 | G34: 2.2 | H34: 1x3C-4mm2 Cu/XLPE/PVC INCLUDING (E) | I34: 3C-4 | J34: 1 | K34: =INDEX(OD_NILAI,MATCH(I34,OD_KODE,0)) -> 13.5 | L34: =J34*K34 -> 13.5 | M34: =J34*PI()/4*K34^2 -> 143.13882
A35: 30 | B35: MEFLV6001 | C35: DB-UTILITY | D35: DB-UTILTY-27 | E35: OUTGOING | F35: SPARE / FUTURE | G35: 0 | H35: FUTURE | J35: 0 | K35: 0 | L35: =J35*K35 -> 0 | M35: =J35*PI()/4*K35^2 -> 0 | N35: Circuit FUTURE/SPARE - belum ada kabel
A36: 31 | B36: MEFLV6001 | C36: DB-UTILITY | D36: DB-UTILTY-28 | E36: OUTGOING | F36: SPARE / FUTURE | G36: 0 | H36: FUTURE | J36: 0 | K36: 0 | L36: =J36*K36 -> 0 | M36: =J36*PI()/4*K36^2 -> 0 | N36: Circuit FUTURE/SPARE - belum ada kabel
A37: 32 | B37: MEFLV6001 | C37: DB-UTILITY | D37: DB-UTILTY-29 | E37: OUTGOING | F37: SPARE / FUTURE | G37: 0 | H37: FUTURE | J37: 0 | K37: 0 | L37: =J37*K37 -> 0 | M37: =J37*PI()/4*K37^2 -> 0 | N37: Circuit FUTURE/SPARE - belum ada kabel
A38: 33 | B38: MEFLV6001 | C38: DB-UTILITY (DEG) | D38: INCOMING | E38: INCOMING | F38: FEEDER PANEL | G38: 0 | H38: 1x4C-6mm2 Cu/XLPE/PVC | I38: 4C-6 | J38: 1 | K38: =INDEX(OD_NILAI,MATCH(I38,OD_KODE,0)) -> 16 | L38: =J38*K38 -> 16 | M38: =J38*PI()/4*K38^2 -> 201.06193 | N38: Feeder dari DEG (Pact 7.99 kW). Daya diisi 0 agar total kW tidak dobel.
A39: 34 | B39: MEFLV6001 | C39: DB-UTILITY (DEG) | D39: INCOMING-E | E39: INCOMING | F39: FEEDER PANEL | G39: 0 | H39: 1C-6mm2 Cu/PVC G/Y | I39: 1C-6 | J39: 1 | K39: =INDEX(OD_NILAI,MATCH(I39,OD_KODE,0)) -> 5.5 | L39: =J39*K39 -> 5.5 | M39: =J39*PI()/4*K39^2 -> 23.758294 | N39: Pembumian feeder DEG
A40: 35 | B40: MEFLV6001 | C40: DB-UTILITY (DEG) | D40: DB-UTILTY-30 | E40: OUTGOING | F40: RECEPTACLE (F)/35 | G40: 0.8 | H40: 1x3C-4mm2 Cu/XLPE/PVC INCLUDING (E) | I40: 3C-4 | J40: 1 | K40: =INDEX(OD_NILAI,MATCH(I40,OD_KODE,0)) -> 13.5 | L40: =J40*K40 -> 13.5 | M40: =J40*PI()/4*K40^2 -> 143.13882
A41: 36 | B41: MEFLV6001 | C41: DB-UTILITY (DEG) | D41: DB-UTILTY-31 | E41: OUTGOING | F41: RECEPTACLE (F)/36 | G41: 0.4 | H41: 1x3C-4mm2 Cu/XLPE/PVC INCLUDING (E) | I41: 3C-4 | J41: 1 | K41: =INDEX(OD_NILAI,MATCH(I41,OD_KODE,0)) -> 13.5 | L41: =J41*K41 -> 13.5 | M41: =J41*PI()/4*K41^2 -> 143.13882
A42: 37 | B42: MEFLV6001 | C42: DB-UTILITY (DEG) | D42: DB-UTILTY-32 | E42: OUTGOING | F42: RECEPTACLE (F)/37 FIRE ALARM | G42: 2 | H42: 1x3C-4mm2 Cu/XLPE/PVC INCLUDING (E) | I42: 3C-4 | J42: 1 | K42: =INDEX(OD_NILAI,MATCH(I42,OD_KODE,0)) -> 13.5 | L42: =J42*K42 -> 13.5 | M42: =J42*PI()/4*K42^2 -> 143.13882
A43: 38 | B43: MEFLV6001 | C43: DB-UTILITY (DEG) | D43: DB-UTILTY-33 | E43: OUTGOING | F43: RECEPTACLE (F)/38 PUBLIC ADDRESS | G43: 2 | H43: 1x3C-4mm2 Cu/XLPE/PVC INCLUDING (E) | I43: 3C-4 | J43: 1 | K43: =INDEX(OD_NILAI,MATCH(I43,OD_KODE,0)) -> 13.5 | L43: =J43*K43 -> 13.5 | M43: =J43*PI()/4*K43^2 -> 143.13882
A44: 39 | B44: MEFLV6001 | C44: DB-UTILITY (DEG) | D44: DB-UTILTY-34 | E44: OUTGOING | F44: RECEPTACLE (F)/39 CCTV | G44: 2 | H44: 1x3C-4mm2 Cu/XLPE/PVC INCLUDING (E) | I44: 3C-4 | J44: 1 | K44: =INDEX(OD_NILAI,MATCH(I44,OD_KODE,0)) -> 13.5 | L44: =J44*K44 -> 13.5 | M44: =J44*PI()/4*K44^2 -> 143.13882
A45: 40 | B45: MEFLV6001 | C45: DB-UTILITY (DEG) | D45: DB-UTILTY-35 | E45: OUTGOING | F45: RECEPTACLE (F)/40 | G45: 0.2 | H45: 1x3C-4mm2 Cu/XLPE/PVC INCLUDING (E) | I45: 3C-4 | J45: 1 | K45: =INDEX(OD_NILAI,MATCH(I45,OD_KODE,0)) -> 13.5 | L45: =J45*K45 -> 13.5 | M45: =J45*PI()/4*K45^2 -> 143.13882
A46: 41 | B46: MEFLV6001 | C46: DB-UTILITY (DEG) | D46: DB-UTILTY-36 | E46: OUTGOING | F46: SPARE / FUTURE | G46: 0 | H46: FUTURE | J46: 0 | K46: 0 | L46: =J46*K46 -> 0 | M46: =J46*PI()/4*K46^2 -> 0 | N46: Circuit FUTURE/SPARE - belum ada kabel
A47: 42 | B47: MEFLV6001 | C47: DB-UTILITY (DEG) | D47: DB-UTILTY-37 | E47: OUTGOING | F47: SPARE / FUTURE | G47: 0 | H47: FUTURE | J47: 0 | K47: 0 | L47: =J47*K47 -> 0 | M47: =J47*PI()/4*K47^2 -> 0 | N47: Circuit FUTURE/SPARE - belum ada kabel
A48: 43 | B48: MEFLV6001 | C48: DB-UTILITY (DEG) | D48: DB-UTILTY-38 | E48: OUTGOING | F48: SPARE / FUTURE | G48: 0 | H48: FUTURE | J48: 0 | K48: 0 | L48: =J48*K48 -> 0 | M48: =J48*PI()/4*K48^2 -> 0 | N48: Circuit FUTURE/SPARE - belum ada kabel
A49: 44 | B49: MEFLV6002 | C49: DB-HVAC UTILITY | D49: INCOMING | E49: INCOMING | F49: FEEDER PANEL | G49: 0 | H49: 1x4C-25mm2 Cu/XLPE/PVC | I49: 4C-25 | J49: 1 | K49: =INDEX(OD_NILAI,MATCH(I49,OD_KODE,0)) -> 27.5 | L49: =J49*K49 -> 27.5 | M49: =J49*PI()/4*K49^2 -> 593.95736 | N49: Feeder utama (Pact 36.24 kW), in cable tray/trunking. Daya diisi 0 agar total kW tidak dobel.
A50: 45 | B50: MEFLV6002 | C50: DB-HVAC UTILITY | D50: INCOMING-E | E50: INCOMING | F50: FEEDER PANEL | G50: 0 | H50: 1C-16mm2 Cu/PVC G/Y | I50: 1C-16 | J50: 1 | K50: =INDEX(OD_NILAI,MATCH(I50,OD_KODE,0)) -> 8 | L50: =J50*K50 -> 8 | M50: =J50*PI()/4*K50^2 -> 50.265482 | N50: Pembumian feeder
A51: 46 | B51: MEFLV6002 | C51: DB-HVAC UTILITY | D51: DB-HVAC-01 | E51: OUTGOING | F51: IU F-001 WORKSHOP (F-005) | G51: 0.1 | H51: 1x3C-4mm2 Cu/XLPE/PVC INCLUDING (E) | I51: 3C-4 | J51: 1 | K51: =INDEX(OD_NILAI,MATCH(I51,OD_KODE,0)) -> 13.5 | L51: =J51*K51 -> 13.5 | M51: =J51*PI()/4*K51^2 -> 143.13882
A52: 47 | B52: MEFLV6002 | C52: DB-HVAC UTILITY | D52: DB-HVAC-02 | E52: OUTGOING | F52: IU F-101 OFFICE (F-101) | G52: 0.2 | H52: 1x3C-4mm2 Cu/XLPE/PVC INCLUDING (E) | I52: 3C-4 | J52: 1 | K52: =INDEX(OD_NILAI,MATCH(I52,OD_KODE,0)) -> 13.5 | L52: =J52*K52 -> 13.5 | M52: =J52*PI()/4*K52^2 -> 143.13882
A53: 48 | B53: MEFLV6002 | C53: DB-HVAC UTILITY | D53: DB-HVAC-03 | E53: OUTGOING | F53: IU F-102 SUPERVISOR RM (F-102) | G53: 0.016 | H53: 1x3C-4mm2 Cu/XLPE/PVC INCLUDING (E) | I53: 3C-4 | J53: 1 | K53: =INDEX(OD_NILAI,MATCH(I53,OD_KODE,0)) -> 13.5 | L53: =J53*K53 -> 13.5 | M53: =J53*PI()/4*K53^2 -> 143.13882
A54: 49 | B54: MEFLV6002 | C54: DB-HVAC UTILITY | D54: DB-HVAC-04 | E54: OUTGOING | F54: IU F-103 MANAGER RM (F-103) | G54: 0.016 | H54: 1x3C-4mm2 Cu/XLPE/PVC INCLUDING (E) | I54: 3C-4 | J54: 1 | K54: =INDEX(OD_NILAI,MATCH(I54,OD_KODE,0)) -> 13.5 | L54: =J54*K54 -> 13.5 | M54: =J54*PI()/4*K54^2 -> 143.13882
...

Sheet SUMMARY BY TYPE
A1: REKAPITULASI KABEL
A3: A. REKAP PER TIPE KABEL
A4: KODE TIPE | B4: DESKRIPSI KABEL | C4: OD (mm) | D4: JML RUN | E4: LEBAR TOTAL (mm) | F4: LUAS TOTAL (mm2) | G4: % THD LEBAR
A5: 3C-4 | B5: 1x3C-4mm2 Cu/XLPE/PVC (N2XY) | C5: =INDEX(OD_NILAI,MATCH(A5,OD_KODE,0)) -> 13.5 | D5: =SUMIF('CABLE SCHEDULE'!$I$6:$I$72,A5,'CABLE SCHEDULE'!$J$6:$J$72) -> 33 | E5: =SUMIF('CABLE SCHEDULE'!$I$6:$I$72,A5,'CABLE SCHEDULE'!$L$6:$L$72) -> 445.5 | F5: =SUMIF('CABLE SCHEDULE'!$I$6:$I$72,A5,'CABLE SCHEDULE'!$M$6:$M$72) -> 4723.5809 | G5: =IFERROR(E5/$E$14,0) -> 0.55897114
A6: 5C-4 | B6: 1x5C-4mm2 Cu/XLPE/PVC (N2XY) | C6: =INDEX(OD_NILAI,MATCH(A6,OD_KODE,0)) -> 16 | D6: =SUMIF('CABLE SCHEDULE'!$I$6:$I$72,A6,'CABLE SCHEDULE'!$J$6:$J$72) -> 12 | E6: =SUMIF('CABLE SCHEDULE'!$I$6:$I$72,A6,'CABLE SCHEDULE'!$L$6:$L$72) -> 192 | F6: =SUMIF('CABLE SCHEDULE'!$I$6:$I$72,A6,'CABLE SCHEDULE'!$M$6:$M$72) -> 2412.7432 | G6: =IFERROR(E6/$E$14,0) -> 0.24090339
A7: 4C-6 | B7: 1x4C-6mm2 Cu/XLPE/PVC (N2XY) | C7: =INDEX(OD_NILAI,MATCH(A7,OD_KODE,0)) -> 16 | D7: =SUMIF('CABLE SCHEDULE'!$I$6:$I$72,A7,'CABLE SCHEDULE'!$J$6:$J$72) -> 1 | E7: =SUMIF('CABLE SCHEDULE'!$I$6:$I$72,A7,'CABLE SCHEDULE'!$L$6:$L$72) -> 16 | F7: =SUMIF('CABLE SCHEDULE'!$I$6:$I$72,A7,'CABLE SCHEDULE'!$M$6:$M$72) -> 201.06193 | G7: =IFERROR(E7/$E$14,0) -> 0.020075282
A8: 4C-25 | B8: 1x4C-25mm2 Cu/XLPE/PVC (N2XY) | C8: =INDEX(OD_NILAI,MATCH(A8,OD_KODE,0)) -> 27.5 | D8: =SUMIF('CABLE SCHEDULE'!$I$6:$I$72,A8,'CABLE SCHEDULE'!$J$6:$J$72) -> 2 | E8: =SUMIF('CABLE SCHEDULE'!$I$6:$I$72,A8,'CABLE SCHEDULE'!$L$6:$L$72) -> 55 | F8: =SUMIF('CABLE SCHEDULE'!$I$6:$I$72,A8,'CABLE SCHEDULE'!$M$6:$M$72) -> 1187.9147 | G8: =IFERROR(E8/$E$14,0) -> 0.069008783
A9: 4C-70 | B9: 1x4C-70mm2 Cu/XLPE/PVC (N2XY) | C9: =INDEX(OD_NILAI,MATCH(A9,OD_KODE,0)) -> 34 | D9: =SUMIF('CABLE SCHEDULE'!$I$6:$I$72,A9,'CABLE SCHEDULE'!$J$6:$J$72) -> 1 | E9: =SUMIF('CABLE SCHEDULE'!$I$6:$I$72,A9,'CABLE SCHEDULE'!$L$6:$L$72) -> 34 | F9: =SUMIF('CABLE SCHEDULE'!$I$6:$I$72,A9,'CABLE SCHEDULE'!$M$6:$M$72) -> 907.92028 | G9: =IFERROR(E9/$E$14,0) -> 0.042659975
A10: 1C-6 | B10: 1C-6mm2 Cu/PVC G/Y (NYA) | C10: =INDEX(OD_NILAI,MATCH(A10,OD_KODE,0)) -> 5.5 | D10: =SUMIF('CABLE SCHEDULE'!$I$6:$I$72,A10,'CABLE SCHEDULE'!$J$6:$J$72) -> 1 | E10: =SUMIF('CABLE SCHEDULE'!$I$6:$I$72,A10,'CABLE SCHEDULE'!$L$6:$L$72) -> 5.5 | F10: =SUMIF('CABLE SCHEDULE'!$I$6:$I$72,A10,'CABLE SCHEDULE'!$M$6:$M$72) -> 23.758294 | G10: =IFERROR(E10/$E$14,0) -> 0.0069008783
A11: 1C-16 | B11: 1C-16mm2 Cu/PVC G/Y (NYA) | C11: =INDEX(OD_NILAI,MATCH(A11,OD_KODE,0)) -> 8 | D11: =SUMIF('CABLE SCHEDULE'!$I$6:$I$72,A11,'CABLE SCHEDULE'!$J$6:$J$72) -> 2 | E11: =SUMIF('CABLE SCHEDULE'!$I$6:$I$72,A11,'CABLE SCHEDULE'!$L$6:$L$72) -> 16 | F11: =SUMIF('CABLE SCHEDULE'!$I$6:$I$72,A11,'CABLE SCHEDULE'!$M$6:$M$72) -> 100.53096 | G11: =IFERROR(E11/$E$14,0) -> 0.020075282
A12: 1C-35 | B12: 1C-35mm2 Cu/PVC G/Y (NYA) | C12: =INDEX(OD_NILAI,MATCH(A12,OD_KODE,0)) -> 11 | D12: =SUMIF('CABLE SCHEDULE'!$I$6:$I$72,A12,'CABLE SCHEDULE'!$J$6:$J$72) -> 1 | E12: =SUMIF('CABLE SCHEDULE'!$I$6:$I$72,A12,'CABLE SCHEDULE'!$L$6:$L$72) -> 11 | F12: =SUMIF('CABLE SCHEDULE'!$I$6:$I$72,A12,'CABLE SCHEDULE'!$M$6:$M$72) -> 95.033178 | G12: =IFERROR(E12/$E$14,0) -> 0.013801757
A13: 2C-2.5F | B13: 1x2C-2.5mm2 Cu/MGT/XLPE/LSZH (FRC) | C13: =INDEX(OD_NILAI,MATCH(A13,OD_KODE,0)) -> 11 | D13: =SUMIF('CABLE SCHEDULE'!$I$6:$I$72,A13,'CABLE SCHEDULE'!$J$6:$J$72) -> 2 | E13: =SUMIF('CABLE SCHEDULE'!$I$6:$I$72,A13,'CABLE SCHEDULE'!$L$6:$L$72) -> 22 | F13: =SUMIF('CABLE SCHEDULE'!$I$6:$I$72,A13,'CABLE SCHEDULE'!$M$6:$M$72) -> 190.06636 | G13: =IFERROR(E13/$E$14,0) -> 0.027603513
A14: TOTAL | D14: =SUM(D5:D13) -> 55 | E14: =SUM(E5:E13) -> 797 | F14: =SUM(F5:F13) -> 9842.6098 | G14: =IFERROR(E14/E14,0) -> 1
A16: B. REKAP PER PANEL
A17: PANEL | B17: GAMBAR | C17: JML CIRCUIT | D17: JML RUN | E17: TOTAL DAYA (kW) | F17: LEBAR TOTAL (mm) | G17: LUAS TOTAL (mm2)
A18: DB-UTILITY | B18: MEFLV6001 | C18: =COUNTIF('CABLE SCHEDULE'!$C$6:$C$72,A18) -> 32 | D18: =SUMIF('CABLE SCHEDULE'!$C$6:$C$72,A18,'CABLE SCHEDULE'!$J$6:$J$72) -> 29 | E18: =SUMIF('CABLE SCHEDULE'!$C$6:$C$72,A18,'CABLE SCHEDULE'!$G$6:$G$72) -> 60.669 | F18: =SUMIF('CABLE SCHEDULE'!$C$6:$C$72,A18,'CABLE SCHEDULE'!$L$6:$L$72) -> 414.5 | G18: =SUMIF('CABLE SCHEDULE'!$C$6:$C$72,A18,'CABLE SCHEDULE'!$M$6:$M$72) -> 4993.3652
A19: DB-UTILITY (DEG) | B19: MEFLV6001 | C19: =COUNTIF('CABLE SCHEDULE'!$C$6:$C$72,A19) -> 11 | D19: =SUMIF('CABLE SCHEDULE'!$C$6:$C$72,A19,'CABLE SCHEDULE'!$J$6:$J$72) -> 8 | E19: =SUMIF('CABLE SCHEDULE'!$C$6:$C$72,A19,'CABLE SCHEDULE'!$G$6:$G$72) -> 7.4 | F19: =SUMIF('CABLE SCHEDULE'!$C$6:$C$72,A19,'CABLE SCHEDULE'!$L$6:$L$72) -> 102.5 | G19: =SUMIF('CABLE SCHEDULE'!$C$6:$C$72,A19,'CABLE SCHEDULE'!$M$6:$M$72) -> 1083.6531
A20: DB-HVAC UTILITY | B20: MEFLV6002 | C20: =COUNTIF('CABLE SCHEDULE'!$C$6:$C$72,A20) -> 15 | D20: =SUMIF('CABLE SCHEDULE'!$C$6:$C$72,A20,'CABLE SCHEDULE'!$J$6:$J$72) -> 12 | E20: =SUMIF('CABLE SCHEDULE'!$C$6:$C$72,A20,'CABLE SCHEDULE'!$G$6:$G$72) -> 33.562 | F20: =SUMIF('CABLE SCHEDULE'!$C$6:$C$72,A20,'CABLE SCHEDULE'!$L$6:$L$72) -> 185.5 | G20: =SUMIF('CABLE SCHEDULE'!$C$6:$C$72,A20,'CABLE SCHEDULE'!$M$6:$M$72) -> 2423.1497
A21: DB-HVAC UTILITY EMERGENCY | B21: MEFLV6003 | C21: =COUNTIF('CABLE SCHEDULE'!$C$6:$C$72,A21) -> 9 | D21: =SUMIF('CABLE SCHEDULE'!$C$6:$C$72,A21,'CABLE SCHEDULE'!$J$6:$J$72) -> 6 | E21: =SUMIF('CABLE SCHEDULE'!$C$6:$C$72,A21,'CABLE SCHEDULE'!$G$6:$G$72) -> 26.54 | F21: =SUMIF('CABLE SCHEDULE'!$C$6:$C$72,A21,'CABLE SCHEDULE'!$L$6:$L$72) -> 94.5 | G21: =SUMIF('CABLE SCHEDULE'!$C$6:$C$72,A21,'CABLE SCHEDULE'!$M$6:$M$72) -> 1342.4418
A22: TOTAL | C22: =SUM(C18:C21) -> 67 | D22: =SUM(D18:D21) -> 55 | E22: =SUM(E18:E21) -> 128.171 | F22: =SUM(F18:F21) -> 797 | G22: =SUM(G18:G21) -> 9842.6098

Sheet TRAY CALCULATION
A1: PERHITUNGAN UKURAN & JUMLAH JALUR CABLE TRAY
A2: Proyek: Panel Schedule DB-UTILITY / DB-HVAC UTILITY / DB-HVAC UTILITY EMERGENCY | Sel KUNING = input yang boleh diubah
A4: A. PARAMETER PERHITUNGAN (INPUT - SEL KUNING)
A5: A1 | B5: Faktor spare / cadangan pengembangan | C5: 0.3 | D5: - | E5: Praktik umum 20-30%. Menyediakan ruang untuk penambahan kabel di kemudian hari.
A6: A2 | B6: Faktor jarak antar kabel | C6: 1.1 | D6: - | E6: 1.00 = kabel bersentuhan rapat. 1.10 = ada jarak 10% untuk pendinginan & kerapian.
A7: A3 | B7: Tinggi / kedalaman tray | C7: 100 | D7: mm | E7: Standar pasaran: 50 / 100 / 150 mm.
A8: A4 | B8: Maksimum fill ratio (rasio pengisian) | C8: 0.4 | D8: - | E8: Batas umum 40% luas penampang tray (NEC 392 / praktik industri).
A9: A5 | B9: Jumlah layer / susunan kabel | C9: 1 | D9: layer | E9: 1 layer = single layer (disarankan). >1 layer WAJIB koreksi KHA (derating).
A10: A6 | B10: Lebar tray standar yang dipilih | C10: 600 | D10: mm | E10: Lebar tray yang akan dipakai di lapangan. Lihat tabel alternatif di blok F.
A12: B. REKAP DATA KABEL (otomatis dari sheet CABLE SCHEDULE)
A13: B1 | B13: Jumlah baris circuit / feeder terdata | C13: =COUNTA('CABLE SCHEDULE'!$D$6:$D$72) -> 67 | D13: baris | E13: Termasuk incoming, pembumian, FRC, dan circuit FUTURE.
A14: B2 | B14: Jumlah RUN kabel aktif (Σ jumlah run) | C14: ='SUMMARY BY TYPE'!$D$14 -> 55 | D14: run | E14: Circuit FUTURE/SPARE = 0 run (belum ada kabel).
A15: B3 | B15: Total lebar kabel Σ OD | C15: ='SUMMARY BY TYPE'!$E$14 -> 797 | D15: mm | E15: Σ (OD x jumlah run) seluruh kabel.
A16: B4 | B16: Total luas penampang kabel Σ A | C16: ='SUMMARY BY TYPE'!$F$14 -> 9842.6098 | D16: mm2 | E16: Σ (π/4 x OD² x jumlah run) seluruh kabel.
A17: B5 | B17: Total daya terpasang | C17: ='SUMMARY BY TYPE'!$E$22 -> 128.171 | D17: kW | E17: Jumlah daya seluruh panel (referensi, tidak dipakai dalam sizing tray).
A19: C. METODE 1 - PENJUMLAHAN DIAMETER (Σ OD)
B20: Rumus: W1 = Σ OD x faktor jarak x (1 + faktor spare) / jumlah layer
A21: C1 | B21: Σ OD seluruh kabel | C21: =$C$15 -> 797 | D21: mm | E21: Dari B3.
A22: C2 | B22: Setelah faktor jarak antar kabel | C22: =$C$21*$C$6 -> 876.7 | D22: mm | E22: C1 x A2.
A23: C3 | B23: Setelah faktor spare | C23: =$C$22*(1+$C$5) -> 1139.71 | D23: mm | E23: C2 x (1 + A1).
A24: C4 | B24: LEBAR TRAY DIBUTUHKAN - METODE 1 | C24: =$C$23/$C$9 -> 1139.71 | D24: mm | E24: C3 dibagi jumlah layer (A5).
A26: D. METODE 2 - FILL RATIO / LUAS PENAMPANG
B27: Rumus: W2 = Σ A x (1 + faktor spare) / fill ratio / tinggi tray / jumlah layer
A28: D1 | B28: Σ A (luas penampang seluruh kabel) | C28: =$C$16 -> 9842.6098 | D28: mm2 | E28: Dari B4.
A29: D2 | B29: Setelah faktor spare | C29: =$C$28*(1+$C$5) -> 12795.393 | D29: mm2 | E29: D1 x (1 + A1).
A30: D3 | B30: Luas tray minimum (setelah fill ratio) | C30: =$C$29/$C$8 -> 31988.482 | D30: mm2 | E30: D2 dibagi fill ratio maksimum (A4).
A31: D4 | B31: LEBAR TRAY DIBUTUHKAN - METODE 2 | C31: =$C$30/$C$7/$C$9 -> 319.88482 | D31: mm | E31: D3 dibagi tinggi tray (A3) dan jumlah layer (A5).
A33: E. HASIL AKHIR & PENGECEKAN
A34: E1 | B34: LEBAR TRAY DIBUTUHKAN (menentukan) | C34: =MAX($C$24,$C$31) -> 1139.71 | D34: mm | E34: Diambil nilai TERBESAR antara Metode 1 (C4) dan Metode 2 (D4).
A35: E2 | B35: Metode yang menentukan | C35: =IF($C$24>=$C$31,"METODE 1 - Σ OD","METODE 2 - FILL RATIO") -> METODE 1 - Σ OD | D35: - | E35: Untuk susunan 1 layer, Metode 1 hampir selalu menentukan.
A36: E3 | B36: Lebar tray standar dipilih | C36: =$C$10 -> 600 | D36: mm | E36: Dari A6.
A37: E4 | B37: JUMLAH JALUR TRAY DIBUTUHKAN | C37: =ROUNDUP($C$34/$C$10,0) -> 2 | D37: jalur | E37: Lebar dibutuhkan (E1) dibagi lebar tray dipilih (A6), dibulatkan ke atas.
A38: E5 | B38: Total lebar tray terpasang | C38: =$C$37*$C$10 -> 1200 | D38: mm | E38: Jumlah jalur (E4) x lebar tray (A6).
A39: E6 | B39: Luas tray tersedia | C39: =$C$37*$C$10*$C$7*$C$9 -> 120000 | D39: mm2 | E39: Jumlah jalur x lebar x tinggi x jumlah layer.
A40: E7 | B40: FILL RATIO AKTUAL | C40: =$C$16/$C$39 -> 0.082021748 | D40: - | E40: Σ A kabel (B4) dibagi luas tray tersedia (E6).
A41: E8 | B41: CEK TERHADAP BATAS FILL RATIO | C41: =IF($C$40<=$C$8,"OK","NOT OK - PERBESAR TRAY") -> OK | D41: - | E41: Fill aktual harus <= fill ratio maksimum (A4).
A42: E9 | B42: Okupansi lebar aktual (Σ OD / lebar terpasang) | C42: =$C$15/($C$37*$C$10*$C$9) -> 0.66416667 | D42: - | E42: Berapa persen lebar tray benar-benar tertutup kabel (belum termasuk spare).
A44: F. TABEL ALTERNATIF LEBAR TRAY STANDAR x JUMLAH LAYER
B45: Jumlah jalur = ROUNDUP( lebar dibutuhkan / lebar tray / layer , 0 ). Lebar dibutuhkan mengikuti parameter blok A kecuali jumlah layer.
B46: LEBAR TRAY (mm) | C46: LEBAR DIBUTUHKAN (mm) | D46: JALUR - 1 LAYER | E46: JALUR - 2 LAYER | F46: JALUR - 3 LAYER | G46: FILL AKTUAL 1 LAYER | H46: CEK 1 LAYER
...
