Workbook

Sheet CABLE DATA (OD)
A1: DATA DIAMETER LUAR KABEL (OD)
A2: PERHITUNGAN CABLE TRAY - FINISH GOOD WAREHOUSE
A3: Sel kuning = input, boleh diubah. Seluruh sheet lain mengambil OD dari tabel ini.
A5: NO | B5: KODE TIPE | C5: KONFIGURASI KABEL | D5: OD (mm) | E5: LUAS 1 KABEL (mm2) | F5: CATATAN
A6: 1 | B6: 3C-2.5 (FRC) | C6: Cu/MGT/XLPE/LSZH 3x2.5mm2 | D6: 12 | E6: =PI()/4*D6^2 -> 113.09734 | F6: Tipikal - verifikasi katalog
A7: 2 | B7: 3C-4 | C7: Cu/XLPE/PVC 3x4mm2 | D7: 13.5 | E7: =PI()/4*D7^2 -> 143.13882 | F7: Tipikal - verifikasi katalog
A8: 3 | B8: 3C-4 (FRC) | C8: Cu/MGT/XLPE/LSZH 3x4mm2 | D8: 14.5 | E8: =PI()/4*D8^2 -> 165.12996 | F8: Tipikal - verifikasi katalog
A9: 4 | B9: 2C-2.5 (FRC) | C9: Cu/MGT/XLPE/LSZH 2x2.5mm2 | D9: 11 | E9: =PI()/4*D9^2 -> 95.033178 | F9: Kabel kontrol fire alarm
A10: 5 | B10: 5C-4 | C10: Cu/XLPE/PVC 5x4mm2 | D10: 16 | E10: =PI()/4*D10^2 -> 201.06193 | F10: Tipikal - verifikasi katalog
A11: 6 | B11: 5C-10 | C11: Cu/XLPE/PVC 5x10mm2 | D11: 21.5 | E11: =PI()/4*D11^2 -> 363.0503 | F11: Tipikal - verifikasi katalog
A12: 7 | B12: 5C-10 (FRC) | C12: Cu/MGT/XLPE/LSZH 5x10mm2 | D12: 23 | E12: =PI()/4*D12^2 -> 415.47563 | F12: FRC lebih besar ~7%
A13: 8 | B13: 5C-16 | C13: Cu/XLPE/PVC 5x16mm2 | D13: 26 | E13: =PI()/4*D13^2 -> 530.92916 | F13: Tipikal - verifikasi katalog
A14: 9 | B14: 4C-16 | C14: Cu/XLPE/PVC 4x16mm2 | D14: 23 | E14: =PI()/4*D14^2 -> 415.47563 | F14: Tipikal - verifikasi katalog
A15: 10 | B15: 4C-25 | C15: Cu/XLPE/PVC 4x25mm2 | D15: 27.5 | E15: =PI()/4*D15^2 -> 593.95736 | F15: Tipikal - verifikasi katalog
A16: 11 | B16: 4C-120 | C16: Cu/XLPE/PVC 4x120mm2 | D16: 50 | E16: =PI()/4*D16^2 -> 1963.4954 | F16: Tipikal - verifikasi katalog
A17: 12 | B17: 4C-240 (FRC) | C17: Cu/MGT/XLPE/LSZH 4x240mm2 | D17: 74 | E17: =PI()/4*D17^2 -> 4300.8403 | F17: FRC lebih besar ~6%
... A21: 16 | B21: 1C-240 | C21: Cu/XLPE/PVC 1x240mm2 | D21: 24.5 | E21: =PI()/4*D21^2 -> 471.43525 | F21: Single core - inti & pembumian
A23: Catatan: nilai OD di atas adalah nilai TIPIKAL kabel Cu/XLPE/PVC (N2XY) pasaran Indonesia.
A24: WAJIB diverifikasi ke katalog pabrikan (Supreme / Kabelindo / Kabelmetal) sebelum dipakai untuk konstruksi.
A25: Kabel FRC (Cu/MGT/XLPE/LSZH) diberi OD lebih besar dari kabel biasa dengan penampang sama.

Sheet CABLE SCHEDULE
A1: CABLE SCHEDULE - REKAP SELURUH KABEL
A2: Sumber: ME-D-LV-6000 / 6001 / 6002 / 6003 (Hanuman Brewery Expansion Phase 3)
A4: NO | B4: PANEL | C4: CIRCUIT No. | D4: KATEGORI | E4: DAYA (kW) | F4: DESKRIPSI KABEL | G4: TIPE | H4: JML RUN | I4: OD (mm) | J4: LEBAR TOTAL (mm) | K4: LUAS TOTAL (mm2)
A5: 1 | B5: MDB-FGW-L0 | C5: INCOMING MDB | D5: INCOMING | E5: 225.32 | F5: 4x(4x1C-240mm2 Cu/XLPE/PVC) dari LVMSB#6.1 | G5: 1C-240 | H5: 16 | I5: =INDEX(OD_LIST,MATCH(G5,TIPE_KODE,0)) -> 24.5 | J5: =I5*H5 -> 392 | K5: =PI()/4*I5^2*H5 -> 7542.964
A6: 2 | B6: MDB-FGW-L0 | C6: INCOMING MDB (E) | D6: INCOMING | F6: E 2x1C-240mm2 Cu/PVC | G6: 1C-240 | H6: 2 | I6: =INDEX(OD_LIST,MATCH(G6,TIPE_KODE,0)) -> 24.5 | J6: =I6*H6 -> 49 | K6: =PI()/4*I6^2*H6 -> 942.8705
A7: 3 | B7: MDB-FGW-L0 | C7: FEEDER DB-FGW-L0-LP | D7: FEEDER | E7: 198.94 | F7: 2x4C-120mm2 Cu/XLPE/PVC | G7: 4C-120 | H7: 2 | I7: =INDEX(OD_LIST,MATCH(G7,TIPE_KODE,0)) -> 50 | J7: =I7*H7 -> 100 | K7: =PI()/4*I7^2*H7 -> 3926.9908
A8: 4 | B8: MDB-FGW-L0 | C8: FEEDER DB-FGW-L0-LP (E) | D8: FEEDER | F8: E 1C-120mm2 Cu/PVC G/Y | G8: 1C-120 | H8: 1 | I8: =INDEX(OD_LIST,MATCH(G8,TIPE_KODE,0)) -> 18.5 | J8: =I8*H8 -> 18.5 | K8: =PI()/4*I8^2*H8 -> 268.80252
A9: 5 | B9: MDB-FGW-L0 | C9: FEEDER CP-FGW-L0-MVAC | D9: FEEDER | E9: 26.38 | F9: 1x4C-25mm2 Cu/XLPE/PVC | G9: 4C-25 | H9: 1 | I9: =INDEX(OD_LIST,MATCH(G9,TIPE_KODE,0)) -> 27.5 | J9: =I9*H9 -> 27.5 | K9: =PI()/4*I9^2*H9 -> 593.95736
A10: 6 | B10: MDB-FGW-L0 | C10: FEEDER CP-FGW-L0-MVAC (E) | D10: FEEDER | F10: E 1C-16mm2 Cu/PVC G/Y | G10: 1C-16 | H10: 1 | I10: =INDEX(OD_LIST,MATCH(G10,TIPE_KODE,0)) -> 8 | J10: =I10*H10 -> 8 | K10: =PI()/4*I10^2*H10 -> 50.265482
A11: 7 | B11: DB-FGW-L0-LP | C11: INCOMING EX DEG | D11: INCOMING | E11: 14.9 | F11: 1x4C-16mm2 Cu/XLPE/PVC | G11: 4C-16 | H11: 1 | I11: =INDEX(OD_LIST,MATCH(G11,TIPE_KODE,0)) -> 23 | J11: =I11*H11 -> 23 | K11: =PI()/4*I11^2*H11 -> 415.47563
A12: 8 | B12: DB-FGW-L0-LP | C12: INCOMING EX DEG (E) | D12: INCOMING | F12: E 1C-16mm2 Cu/PVC G/Y | G12: 1C-16 | H12: 1 | I12: =INDEX(OD_LIST,MATCH(G12,TIPE_KODE,0)) -> 8 | J12: =I12*H12 -> 8 | K12: =PI()/4*I12^2*H12 -> 50.265482
A13: 9 | B13: DB-FGW-L0-LP | C13: KONTROL FIRE ALARM | D13: KONTROL | F13: 1x2C-2.5mm2 Cu/MGT/XLPE/LSZH (FRC) | G13: 2C-2.5 (FRC) | H13: 1 | I13: =INDEX(OD_LIST,MATCH(G13,TIPE_KODE,0)) -> 11 | J13: =I13*H13 -> 11 | K13: =PI()/4*I13^2*H13 -> 95.033178
A14: 10 | B14: DB-FGW-L0-LP | C14: DB-FGW-L0-LP-L1 | D14: OUTGOING | E14: 1.35 | F14: 1x3C-4mm2 Cu/XLPE/PVC INCLUDING (E) | G14: 3C-4 | H14: 1 | I14: =INDEX(OD_LIST,MATCH(G14,TIPE_KODE,0)) -> 13.5 | J14: =I14*H14 -> 13.5 | K14: =PI()/4*I14^2*H14 -> 143.13882
A15: 11 | B15: DB-FGW-L0-LP | C15: DB-FGW-L0-LP-L2 | D15: OUTGOING | E15: 1.2 | F15: 1x3C-4mm2 Cu/XLPE/PVC INCLUDING (E) | G15: 3C-4 | H15: 1 | I15: =INDEX(OD_LIST,MATCH(G15,TIPE_KODE,0)) -> 13.5 | J15: =I15*H15 -> 13.5 | K15: =PI()/4*I15^2*H15 -> 143.13882
A16: 12 | B16: DB-FGW-L0-LP | C16: DB-FGW-L0-LP-L3 | D16: OUTGOING | E16: 1.5 | F16: 1x3C-4mm2 Cu/XLPE/PVC INCLUDING (E) | G16: 3C-4 | H16: 1 | I16: =INDEX(OD_LIST,MATCH(G16,TIPE_KODE,0)) -> 13.5 | J16: =I16*H16 -> 13.5 | K16: =PI()/4*I16^2*H16 -> 143.13882
A17: 13 | B17: DB-FGW-L0-LP | C17: DB-FGW-L0-LP-L4 | D17: OUTGOING | E17: 1.5 | F17: 1x3C-4mm2 Cu/XLPE/PVC INCLUDING (E) | G17: 3C-4 | H17: 1 | I17: =INDEX(OD_LIST,MATCH(G17,TIPE_KODE,0)) -> 13.5 | J17: =I17*H17 -> 13.5 | K17: =PI()/4*I17^2*H17 -> 143.13882
A18: 14 | B18: DB-FGW-L0-LP | C18: DB-FGW-L0-LP-L5 | D18: OUTGOING | E18: 1.5 | F18: 1x3C-4mm2 Cu/XLPE/PVC INCLUDING (E) | G18: 3C-4 | H18: 1 | I18: =INDEX(OD_LIST,MATCH(G18,TIPE_KODE,0)) -> 13.5 | J18: =I18*H18 -> 13.5 | K18: =PI()/4*I18^2*H18 -> 143.13882
A19: 15 | B19: DB-FGW-L0-LP | C19: DB-FGW-L0-LP-L6 | D19: OUTGOING | E19: 1.5 | F19: 1x3C-4mm2 Cu/XLPE/PVC INCLUDING (E) | G19: 3C-4 | H19: 1 | I19: =INDEX(OD_LIST,MATCH(G19,TIPE_KODE,0)) -> 13.5 | J19: =I19*H19 -> 13.5 | K19: =PI()/4*I19^2*H19 -> 143.13882
A20: 16 | B20: DB-FGW-L0-LP | C20: DB-FGW-L0-LP-L7 | D20: OUTGOING | E20: 1.5 | F20: 1x3C-4mm2 Cu/XLPE/PVC INCLUDING (E) | G20: 3C-4 | H20: 1 | I20: =INDEX(OD_LIST,MATCH(G20,TIPE_KODE,0)) -> 13.5 | J20: =I20*H20 -> 13.5 | K20: =PI()/4*I20^2*H20 -> 143.13882
A21: 17 | B21: DB-FGW-L0-LP | C21: DB-FGW-L0-LP-L8 | D21: OUTGOING | E21: 1.5 | F21: 1x3C-4mm2 Cu/XLPE/PVC INCLUDING (E) | G21: 3C-4 | H21: 1 | I21: =INDEX(OD_LIST,MATCH(G21,TIPE_KODE,0)) -> 13.5 | J21: =I21*H21 -> 13.5 | K21: =PI()/4*I21^2*H21 -> 143.13882
A22: 18 | B22: DB-FGW-L0-LP | C22: DB-FGW-L0-LP-L9 | D22: OUTGOING | E22: 1.5 | F22: 1x3C-4mm2 Cu/XLPE/PVC INCLUDING (E) | G22: 3C-4 | H22: 1 | I22: =INDEX(OD_LIST,MATCH(G22,TIPE_KODE,0)) -> 13.5 | J22: =I22*H22 -> 13.5 | K22: =PI()/4*I22^2*H22 -> 143.13882
A23: 19 | B23: DB-FGW-L0-LP | C23: DB-FGW-L0-LP-L10 | D23: OUTGOING | E23: 1.5 | F23: 1x3C-4mm2 Cu/XLPE/PVC INCLUDING (E) | G23: 3C-4 | H23: 1 | I23: =INDEX(OD_LIST,MATCH(G23,TIPE_KODE,0)) -> 13.5 | J23: =I23*H23 -> 13.5 | K23: =PI()/4*I23^2*H23 -> 143.13882
A24: 20 | B24: DB-FGW-L0-LP | C24: DB-FGW-L0-LP-L11 | D24: OUTGOING | E24: 1.5 | F24: 1x3C-4mm2 Cu/XLPE/PVC INCLUDING (E) | G24: 3C-4 | H24: 1 | I24: =INDEX(OD_LIST,MATCH(G24,TIPE_KODE,0)) -> 13.5 | J24: =I24*H24 -> 13.5 | K24: =PI()/4*I24^2*H24 -> 143.13882
A25: 21 | B25: DB-FGW-L0-LP | C25: DB-FGW-L0-LP-L12 | D25: OUTGOING | E25: 1.5 | F25: 1x3C-4mm2 Cu/XLPE/PVC INCLUDING (E) | G25: 3C-4 | H25: 1 | I25: =INDEX(OD_LIST,MATCH(G25,TIPE_KODE,0)) -> 13.5 | J25: =I25*H25 -> 13.5 | K25: =PI()/4*I25^2*H25 -> 143.13882
... A140: 136 | B140: CP-FGW-L1-MVAC | C140: INCOMING EX DEG | D140: INCOMING | E140: 579.16 | F140: 4x(1x4C-240mm2 Cu/MGT/XLPE/LSZH (FRC)) | G140: 4C-240 (FRC) | H140: 4 | I140: =INDEX(OD_LIST,MATCH(G140,TIPE_KODE,0)) -> 74 | J140: =I140*H140 -> 296 | K140: =PI()/4*I140^2*H140 -> 17203.361
A141: 137 | B141: CP-FGW-L1-MVAC | C141: INCOMING EX DEG (E) | D141: INCOMING | F141: 2x(1C-120mm2 Cu/LSZH G/Y) | G141: 1C-120 (FRC) | H141: 2 | I141: =INDEX(OD_LIST,MATCH(G141,TIPE_KODE,0)) -> 19.5 | J141: =I141*H141 -> 39 | K141: =PI()/4*I141^2*H141 -> 597.2953
A142: 138 | B142: CP-FGW-L1-MVAC | C142: KONTROL FIRE ALARM | D142: KONTROL | F142: 1x2C-2.5mm2 Cu/MGT/XLPE/LSZH (FRC) | G142: 2C-2.5 (FRC) | H142: 1 | I142: =INDEX(OD_LIST,MATCH(G142,TIPE_KODE,0)) -> 11 | J142: =I142*H142 -> 11 | K142: =PI()/4*I142^2*H142 -> 95.033178
A143: 139 | B143: CP-FGW-L1-MVAC | C143: CP-FGW-L1-MVAC-01 | D143: OUTGOING | E143: 19.152 | F143: 1x5C-10mm2 Cu/XLPE/PVC INCLUDING (E) | G143: 5C-10 | H143: 1 | I143: =INDEX(OD_LIST,MATCH(G143,TIPE_KODE,0)) -> 21.5 | J143: =I143*H143 -> 21.5 | K143: =PI()/4*I143^2*H143 -> 363.0503
A144: 140 | B144: CP-FGW-L1-MVAC | C144: CP-FGW-L1-MVAC-02 | D144: OUTGOING | E144: 19.152 | F144: 1x5C-10mm2 Cu/XLPE/PVC INCLUDING (E) | G144: 5C-10 | H144: 1 | I144: =INDEX(OD_LIST,MATCH(G144,TIPE_KODE,0)) -> 21.5 | J144: =I144*H144 -> 21.5 | K144: =PI()/4*I144^2*H144 -> 363.0503
A145: 141 | B145: CP-FGW-L1-MVAC | C145: CP-FGW-L1-MVAC-03 | D145: OUTGOING | E145: 19.152 | F145: 1x5C-10mm2 Cu/XLPE/PVC INCLUDING (E) | G145: 5C-10 | H145: 1 | I145: =INDEX(OD_LIST,MATCH(G145,TIPE_KODE,0)) -> 21.5 | J145: =I145*H145 -> 21.5 | K145: =PI()/4*I145^2*H145 -> 363.0503
A146: 142 | B146: CP-FGW-L1-MVAC | C146: CP-FGW-L1-MVAC-04 | D146: OUTGOING | E146: 19.152 | F146: 1x5C-10mm2 Cu/XLPE/PVC INCLUDING (E) | G146: 5C-10 | H146: 1 | I146: =INDEX(OD_LIST,MATCH(G146,TIPE_KODE,0)) -> 21.5 | J146: =I146*H146 -> 21.5 | K146: =PI()/4*I146^2*H146 -> 363.0503
A147: 143 | B147: CP-FGW-L1-MVAC | C147: CP-FGW-L1-MVAC-05 | D147: OUTGOING | E147: 19.152 | F147: 1x5C-10mm2 Cu/XLPE/PVC INCLUDING (E) | G147: 5C-10 | H147: 1 | I147: =INDEX(OD_LIST,MATCH(G147,TIPE_KODE,0)) -> 21.5 | J147: =I147*H147 -> 21.5 | K147: =PI()/4*I147^2*H147 -> 363.0503
A148: 144 | B148: CP-FGW-L1-MVAC | C148: CP-FGW-L1-MVAC-06 | D148: OUTGOING | E148: 19.152 | F148: 1x5C-10mm2 Cu/XLPE/PVC INCLUDING (E) | G148: 5C-10 | H148: 1 | I148: =INDEX(OD_LIST,MATCH(G148,TIPE_KODE,0)) -> 21.5 | J148: =I148*H148 -> 21.5 | K148: =PI()/4*I148^2*H148 -> 363.0503
A149: 145 | B149: CP-FGW-L1-MVAC | C149: CP-FGW-L1-MVAC-07 | D149: OUTGOING | E149: 19.152 | F149: 1x5C-10mm2 Cu/XLPE/PVC INCLUDING (E) | G149: 5C-10 | H149: 1 | I149: =INDEX(OD_LIST,MATCH(G149,TIPE_KODE,0)) -> 21.5 | J149: =I149*H149 -> 21.5 | K149: =PI()/4*I149^2*H149 -> 363.0503
A150: 146 | B150: CP-FGW-L1-MVAC | C150: CP-FGW-L1-MVAC-08 | D150: OUTGOING | E150: 19.152 | F150: 1x5C-10mm2 Cu/XLPE/PVC INCLUDING (E) | G150: 5C-10 | H150: 1 | I150: =INDEX(OD_LIST,MATCH(G150,TIPE_KODE,0)) -> 21.5 | J150: =I150*H150 -> 21.5 | K150: =PI()/4*I150^2*H150 -> 363.0503
A151: 147 | B151: CP-FGW-L1-MVAC | C151: CP-FGW-L1-MVAC-09 | D151: OUTGOING | E151: 19.152 | F151: 1x5C-10mm2 Cu/MGT/XLPE/LSZH INCLUDING (E) | G151: 5C-10 (FRC) | H151: 1 | I151: =INDEX(OD_LIST,MATCH(G151,TIPE_KODE,0)) -> 23 | J151: =I151*H151 -> 23 | K151: =PI()/4*I151^2*H151 -> 415.47563
A152: 148 | B152: CP-FGW-L1-MVAC | C152: CP-FGW-L1-MVAC-10 | D152: OUTGOING | E152: 19.152 | F152: 1x5C-10mm2 Cu/MGT/XLPE/LSZH INCLUDING (E) | G152: 5C-10 (FRC) | H152: 1 | I152: =INDEX(OD_LIST,MATCH(G152,TIPE_KODE,0)) -> 23 | J152: =I152*H152 -> 23 | K152: =PI()/4*I152^2*H152 -> 415.47563
A153: 149 | B153: CP-FGW-L1-MVAC | C153: CP-FGW-L1-MVAC-11 | D153: OUTGOING | E153: 19.152 | F153: 1x5C-10mm2 Cu/MGT/XLPE/LSZH INCLUDING (E) | G153: 5C-10 (FRC) | H153: 1 | I153: =INDEX(OD_LIST,MATCH(G153,TIPE_KODE,0)) -> 23 | J153: =I153*H153 -> 23 | K153: =PI()/4*I153^2*H153 -> 415.47563
A154: 150 | B154: CP-FGW-L1-MVAC | C154: CP-FGW-L1-MVAC-12 | D154: OUTGOING | E154: 19.152 | F154: 1x5C-10mm2 Cu/MGT/XLPE/LSZH INCLUDING (E) | G154: 5C-10 (FRC) | H154: 1 | I154: =INDEX(OD_LIST,MATCH(G154,TIPE_KODE,0)) -> 23 | J154: =I154*H154 -> 23 | K154: =PI()/4*I154^2*H154 -> 415.47563
... A170: 166 | B170: CP-FGW-L1-MVAC | C170: CP-FGW-L1-MVAC-28 | D170: OUTGOING | E170: 19.152 | F170: 1x5C-10mm2 Cu/MGT/XLPE/LSZH INCLUDING (E) | G170: 5C-10 (FRC) | H170: 1 | I170: =INDEX(OD_LIST,MATCH(G170,TIPE_KODE,0)) -> 23 | J170: =I170*H170 -> 23 | K170: =PI()/4*I170^2*H170 -> 415.47563
...

Sheet SUMMARY BY TYPE
A1: REKAPITULASI KABEL
A3: A. REKAP PER TIPE KABEL
A4: NO | B4: TIPE KABEL | C4: JML RUN | D4: OD (mm) | E4: LEBAR TOTAL (mm) | F4: LUAS TOTAL (mm2) | G4: % THD LEBAR
A5: 1 | B5: 1C-120 | C5: =SUMIF('CABLE SCHEDULE'!$G$5:$G$170,B5,'CABLE SCHEDULE'!$H$5:$H$170) -> 1 | D5: =INDEX(OD_LIST,MATCH(B5,TIPE_KODE,0)) -> 18.5 | E5: =SUMIF('CABLE SCHEDULE'!$G$5:$G$170,B5,'CABLE SCHEDULE'!$J$5:$J$170) -> 18.5 | F5: =SUMIF('CABLE SCHEDULE'!$G$5:$G$170,B5,'CABLE SCHEDULE'!$K$5:$K$170) -> 268.80252 | G5: =IF($E$21=0,0,E5/$E$21) -> 0.0054749926
A6: 2 | B6: 1C-120 (FRC) | C6: =SUMIF('CABLE SCHEDULE'!$G$5:$G$170,B6,'CABLE SCHEDULE'!$H$5:$H$170) -> 2 | D6: =INDEX(OD_LIST,MATCH(B6,TIPE_KODE,0)) -> 19.5 | E6: =SUMIF('CABLE SCHEDULE'!$G$5:$G$170,B6,'CABLE SCHEDULE'!$J$5:$J$170) -> 39 | F6: =SUMIF('CABLE SCHEDULE'!$G$5:$G$170,B6,'CABLE SCHEDULE'!$K$5:$K$170) -> 597.2953 | G6: =IF($E$21=0,0,E6/$E$21) -> 0.011541876
A7: 3 | B7: 1C-16 | C7: =SUMIF('CABLE SCHEDULE'!$G$5:$G$170,B7,'CABLE SCHEDULE'!$H$5:$H$170) -> 2 | D7: =INDEX(OD_LIST,MATCH(B7,TIPE_KODE,0)) -> 8 | E7: =SUMIF('CABLE SCHEDULE'!$G$5:$G$170,B7,'CABLE SCHEDULE'!$J$5:$J$170) -> 16 | F7: =SUMIF('CABLE SCHEDULE'!$G$5:$G$170,B7,'CABLE SCHEDULE'!$K$5:$K$170) -> 100.53096 | G7: =IF($E$21=0,0,E7/$E$21) -> 0.0047351287
A8: 4 | B8: 1C-240 | C8: =SUMIF('CABLE SCHEDULE'!$G$5:$G$170,B8,'CABLE SCHEDULE'!$H$5:$H$170) -> 18 | D8: =INDEX(OD_LIST,MATCH(B8,TIPE_KODE,0)) -> 24.5 | E8: =SUMIF('CABLE SCHEDULE'!$G$5:$G$170,B8,'CABLE SCHEDULE'!$J$5:$J$170) -> 441 | F8: =SUMIF('CABLE SCHEDULE'!$G$5:$G$170,B8,'CABLE SCHEDULE'!$K$5:$K$170) -> 8485.8345 | G8: =IF($E$21=0,0,E8/$E$21) -> 0.13051199
A9: 5 | B9: 2C-2.5 (FRC) | C9: =SUMIF('CABLE SCHEDULE'!$G$5:$G$170,B9,'CABLE SCHEDULE'!$H$5:$H$170) -> 2 | D9: =INDEX(OD_LIST,MATCH(B9,TIPE_KODE,0)) -> 11 | E9: =SUMIF('CABLE SCHEDULE'!$G$5:$G$170,B9,'CABLE SCHEDULE'!$J$5:$J$170) -> 22 | F9: =SUMIF('CABLE SCHEDULE'!$G$5:$G$170,B9,'CABLE SCHEDULE'!$K$5:$K$170) -> 190.06636 | G9: =IF($E$21=0,0,E9/$E$21) -> 0.006510802
A10: 6 | B10: 3C-2.5 (FRC) | C10: =SUMIF('CABLE SCHEDULE'!$G$5:$G$170,B10,'CABLE SCHEDULE'!$H$5:$H$170) -> 7 | D10: =INDEX(OD_LIST,MATCH(B10,TIPE_KODE,0)) -> 12 | E10: =SUMIF('CABLE SCHEDULE'!$G$5:$G$170,B10,'CABLE SCHEDULE'!$J$5:$J$170) -> 84 | F10: =SUMIF('CABLE SCHEDULE'!$G$5:$G$170,B10,'CABLE SCHEDULE'!$K$5:$K$170) -> 791.68135 | G10: =IF($E$21=0,0,E10/$E$21) -> 0.024859426
A11: 7 | B11: 3C-4 | C11: =SUMIF('CABLE SCHEDULE'!$G$5:$G$170,B11,'CABLE SCHEDULE'!$H$5:$H$170) -> 101 | D11: =INDEX(OD_LIST,MATCH(B11,TIPE_KODE,0)) -> 13.5 | E11: =SUMIF('CABLE SCHEDULE'!$G$5:$G$170,B11,'CABLE SCHEDULE'!$J$5:$J$170) -> 1363.5 | F11: =SUMIF('CABLE SCHEDULE'!$G$5:$G$170,B11,'CABLE SCHEDULE'!$K$5:$K$170) -> 14457.02 | G11: =IF($E$21=0,0,E11/$E$21) -> 0.40352175
A12: 8 | B12: 3C-4 (FRC) | C12: =SUMIF('CABLE SCHEDULE'!$G$5:$G$170,B12,'CABLE SCHEDULE'!$H$5:$H$170) -> 1 | D12: =INDEX(OD_LIST,MATCH(B12,TIPE_KODE,0)) -> 14.5 | E12: =SUMIF('CABLE SCHEDULE'!$G$5:$G$170,B12,'CABLE SCHEDULE'!$J$5:$J$170) -> 14.5 | F12: =SUMIF('CABLE SCHEDULE'!$G$5:$G$170,B12,'CABLE SCHEDULE'!$K$5:$K$170) -> 165.12996 | G12: =IF($E$21=0,0,E12/$E$21) -> 0.0042912104
A13: 9 | B13: 4C-120 | C13: =SUMIF('CABLE SCHEDULE'!$G$5:$G$170,B13,'CABLE SCHEDULE'!$H$5:$H$170) -> 2 | D13: =INDEX(OD_LIST,MATCH(B13,TIPE_KODE,0)) -> 50 | E13: =SUMIF('CABLE SCHEDULE'!$G$5:$G$170,B13,'CABLE SCHEDULE'!$J$5:$J$170) -> 100 | F13: =SUMIF('CABLE SCHEDULE'!$G$5:$G$170,B13,'CABLE SCHEDULE'!$K$5:$K$170) -> 3926.9908 | G13: =IF($E$21=0,0,E13/$E$21) -> 0.029594555
A14: 10 | B14: 4C-16 | C14: =SUMIF('CABLE SCHEDULE'!$G$5:$G$170,B14,'CABLE SCHEDULE'!$H$5:$H$170) -> 1 | D14: =INDEX(OD_LIST,MATCH(B14,TIPE_KODE,0)) -> 23 | E14: =SUMIF('CABLE SCHEDULE'!$G$5:$G$170,B14,'CABLE SCHEDULE'!$J$5:$J$170) -> 23 | F14: =SUMIF('CABLE SCHEDULE'!$G$5:$G$170,B14,'CABLE SCHEDULE'!$K$5:$K$170) -> 415.47563 | G14: =IF($E$21=0,0,E14/$E$21) -> 0.0068067476
A15: 11 | B15: 4C-240 (FRC) | C15: =SUMIF('CABLE SCHEDULE'!$G$5:$G$170,B15,'CABLE SCHEDULE'!$H$5:$H$170) -> 4 | D15: =INDEX(OD_LIST,MATCH(B15,TIPE_KODE,0)) -> 74 | E15: =SUMIF('CABLE SCHEDULE'!$G$5:$G$170,B15,'CABLE SCHEDULE'!$J$5:$J$170) -> 296 | F15: =SUMIF('CABLE SCHEDULE'!$G$5:$G$170,B15,'CABLE SCHEDULE'!$K$5:$K$170) -> 17203.361 | G15: =IF($E$21=0,0,E15/$E$21) -> 0.087599882
A16: 12 | B16: 4C-25 | C16: =SUMIF('CABLE SCHEDULE'!$G$5:$G$170,B16,'CABLE SCHEDULE'!$H$5:$H$170) -> 1 | D16: =INDEX(OD_LIST,MATCH(B16,TIPE_KODE,0)) -> 27.5 | E16: =SUMIF('CABLE SCHEDULE'!$G$5:$G$170,B16,'CABLE SCHEDULE'!$J$5:$J$170) -> 27.5 | F16: =SUMIF('CABLE SCHEDULE'!$G$5:$G$170,B16,'CABLE SCHEDULE'!$K$5:$K$170) -> 593.95736 | G16: =IF($E$21=0,0,E16/$E$21) -> 0.0081385025
... A20: 16 | B20: 5C-4 | C20: =SUMIF('CABLE SCHEDULE'!$G$5:$G$170,B20,'CABLE SCHEDULE'!$H$5:$H$170) -> 14 | D20: =INDEX(OD_LIST,MATCH(B20,TIPE_KODE,0)) -> 16 | E20: =SUMIF('CABLE SCHEDULE'!$G$5:$G$170,B20,'CABLE SCHEDULE'!$J$5:$J$170) -> 224 | F20: =SUMIF('CABLE SCHEDULE'!$G$5:$G$170,B20,'CABLE SCHEDULE'!$K$5:$K$170) -> 2814.867 | G20: =IF($E$21=0,0,E20/$E$21) -> 0.066291802
B21: TOTAL | C21: =SUM(C5:C20) -> 187 | E21: =SUM(E5:E20) -> 3379 | F21: =SUM(F5:F20) -> 62817.716 | G21: =SUM(G5:G20) -> 1
A23: B. REKAP PER PANEL
A24: NO | B24: PANEL | C24: JML RUN | D24: DAYA (kW) | E24: LEBAR TOTAL (mm) | F24: LUAS TOTAL (mm2) | G24: % THD LEBAR
A25: 1 | B25: MDB-FGW-L0 | C25: =SUMIF('CABLE SCHEDULE'!$B$5:$B$170,B25,'CABLE SCHEDULE'!$H$5:$H$170) -> 23 | D25: =SUMIF('CABLE SCHEDULE'!$B$5:$B$170,B25,'CABLE SCHEDULE'!$E$5:$E$170) -> 450.64 | E25: =SUMIF('CABLE SCHEDULE'!$B$5:$B$170,B25,'CABLE SCHEDULE'!$J$5:$J$170) -> 595 | F25: =SUMIF('CABLE SCHEDULE'!$B$5:$B$170,B25,'CABLE SCHEDULE'!$K$5:$K$170) -> 13325.851 | G25: =IF($E$29=0,0,E25/$E$29) -> 0.1760876
A26: 2 | B26: DB-FGW-L0-LP | C26: =SUMIF('CABLE SCHEDULE'!$B$5:$B$170,B26,'CABLE SCHEDULE'!$H$5:$H$170) -> 110 | D26: =SUMIF('CABLE SCHEDULE'!$B$5:$B$170,B26,'CABLE SCHEDULE'!$E$5:$E$170) -> 212.912 | E26: =SUMIF('CABLE SCHEDULE'!$B$5:$B$170,B26,'CABLE SCHEDULE'!$J$5:$J$170) -> 1537 | F26: =SUMIF('CABLE SCHEDULE'!$B$5:$B$170,B26,'CABLE SCHEDULE'!$K$5:$K$170) -> 17274.833 | G26: =IF($E$29=0,0,E26/$E$29) -> 0.4548683
A27: 3 | B27: CP-FGW-L0-MVAC | C27: =SUMIF('CABLE SCHEDULE'!$B$5:$B$170,B27,'CABLE SCHEDULE'!$H$5:$H$170) -> 19 | D27: =SUMIF('CABLE SCHEDULE'!$B$5:$B$170,B27,'CABLE SCHEDULE'!$E$5:$E$170) -> 26.385 | E27: =SUMIF('CABLE SCHEDULE'!$B$5:$B$170,B27,'CABLE SCHEDULE'!$J$5:$J$170) -> 269 | F27: =SUMIF('CABLE SCHEDULE'!$B$5:$B$170,B27,'CABLE SCHEDULE'!$K$5:$K$170) -> 3107.4278 | G27: =IF($E$29=0,0,E27/$E$29) -> 0.079609352
A28: 4 | B28: CP-FGW-L1-MVAC | C28: =SUMIF('CABLE SCHEDULE'!$B$5:$B$170,B28,'CABLE SCHEDULE'!$H$5:$H$170) -> 35 | D28: =SUMIF('CABLE SCHEDULE'!$B$5:$B$170,B28,'CABLE SCHEDULE'!$E$5:$E$170) -> 1115.416 | E28: =SUMIF('CABLE SCHEDULE'!$B$5:$B$170,B28,'CABLE SCHEDULE'!$J$5:$J$170) -> 978 | F28: =SUMIF('CABLE SCHEDULE'!$B$5:$B$170,B28,'CABLE SCHEDULE'!$K$5:$K$170) -> 29109.605 | G28: =IF($E$29=0,0,E28/$E$29) -> 0.28943474
B29: TOTAL | C29: =SUM(C25:C28) -> 187 | D29: =SUM(D25:D28) -> 1805.353 | E29: =SUM(E25:E28) -> 3379 | F29: =SUM(F25:F28) -> 62817.716 | G29: =SUM(G25:G28) -> 1
A30: Catatan: kolom DAYA bersifat informatif - kabel feeder antar panel dan beban outgoing panel tujuan tercatat ganda.
A32: C. REKAP PER KATEGORI
A33: NO | B33: KATEGORI | C33: JML RUN | D33: LEBAR TOTAL (mm) | E33: LUAS TOTAL (mm2)
A34: 1 | B34: INCOMING | C34: =SUMIF('CABLE SCHEDULE'!$D$5:$D$170,B34,'CABLE SCHEDULE'!$H$5:$H$170) -> 26 | D34: =SUMIF('CABLE SCHEDULE'!$D$5:$D$170,B34,'CABLE SCHEDULE'!$J$5:$J$170) -> 807 | E34: =SUMIF('CABLE SCHEDULE'!$D$5:$D$170,B34,'CABLE SCHEDULE'!$K$5:$K$170) -> 26752.232
A35: 2 | B35: FEEDER | C35: =SUMIF('CABLE SCHEDULE'!$D$5:$D$170,B35,'CABLE SCHEDULE'!$H$5:$H$170) -> 5 | D35: =SUMIF('CABLE SCHEDULE'!$D$5:$D$170,B35,'CABLE SCHEDULE'!$J$5:$J$170) -> 154 | E35: =SUMIF('CABLE SCHEDULE'!$D$5:$D$170,B35,'CABLE SCHEDULE'!$K$5:$K$170) -> 4840.0162
A36: 3 | B36: OUTGOING | C36: =SUMIF('CABLE SCHEDULE'!$D$5:$D$170,B36,'CABLE SCHEDULE'!$H$5:$H$170) -> 154 | D36: =SUMIF('CABLE SCHEDULE'!$D$5:$D$170,B36,'CABLE SCHEDULE'!$J$5:$J$170) -> 2396 | E36: =SUMIF('CABLE SCHEDULE'!$D$5:$D$170,B36,'CABLE SCHEDULE'!$K$5:$K$170) -> 31035.401
A37: 4 | B37: KONTROL | C37: =SUMIF('CABLE SCHEDULE'!$D$5:$D$170,B37,'CABLE SCHEDULE'!$H$5:$H$170) -> 2 | D37: =SUMIF('CABLE SCHEDULE'!$D$5:$D$170,B37,'CABLE SCHEDULE'!$J$5:$J$170) -> 22 | E37: =SUMIF('CABLE SCHEDULE'!$D$5:$D$170,B37,'CABLE SCHEDULE'!$K$5:$K$170) -> 190.06636

Sheet TRAY CALCULATION
A1: PERHITUNGAN UKURAN & JUMLAH JALUR CABLE TRAY
A2: Finish Good Warehouse - MDB-FGW-L0, DB-FGW-L0-LP, CP-FGW-L0-MVAC, CP-FGW-L1-MVAC
A4: A. PARAMETER PERHITUNGAN (sel kuning = input)
A5: Faktor spare / cadangan pengembangan | C5: 0.3
A6: Faktor jarak antar kabel (1.00 = bersentuhan) | C6: 1.1
A7: Tinggi cable tray | C7: 100 | D7: mm
A8: Maksimum fill ratio (luas) | C8: 0.4
A9: Jumlah layer / susunan kabel | C9: 1 | D9: layer
A10: Lebar tray standar yang dipilih | C10: 600 | D10: mm
A12: B. REKAP DATA KABEL (link dari CABLE SCHEDULE)
A13: Jumlah run kabel total | C13: ='CABLE SCHEDULE'!H171 -> 187 | D13: run
A14: Jumlah OD seluruh kabel (SOD) | C14: ='CABLE SCHEDULE'!J171 -> 3379 | D14: mm
A15: Jumlah luas penampang kabel (SA) | C15: ='CABLE SCHEDULE'!K171 -> 62817.716 | D15: mm2
A16: Total kolom daya - informatif saja | C16: ='CABLE SCHEDULE'!E171 -> 1805.353 | D16: kW (feeder & outgoing tercatat ganda, bukan daya bersih)
A18: C. METODE 1 - PENJUMLAHAN DIAMETER (SOD)
A19: W1 = SOD x faktor jarak x (1 + spare) / layer
A20: Lebar dibutuhkan metode 1 | C20: =$C$14*$C$6*(1+$C$5)/$C$9 -> 4831.97 | D20: mm
A22: D. METODE 2 - FILL RATIO / LUAS
A23: W2 = SA x (1 + spare) / fill ratio / tinggi tray / layer
A24: Lebar dibutuhkan metode 2 | C24: =$C$15*(1+$C$5)/$C$8/$C$7/$C$9 -> 2041.5758 | D24: mm
A26: E. HASIL PERHITUNGAN
A27: LEBAR TRAY DIBUTUHKAN = MAX(W1 ; W2) | C27: =MAX($C$20,$C$24) -> 4831.97 | D27: mm
A28: Metode yang menentukan | C28: =IF($C$20>=$C$24,"METODE 1 (SOD)","METODE 2 (FILL)") -> METODE 1 (SOD)
A29: Lebar tray standar dipilih | C29: =$C$10 -> 600 | D29: mm
A30: JUMLAH JALUR TRAY DIBUTUHKAN | C30: =ROUNDUP($C$27/$C$10,0) -> 9 | D30: jalur
A31: Luas tray tersedia total | C31: =$C$30*$C$10*$C$7*$C$9 -> 540000 | D31: mm2
A32: FILL RATIO AKTUAL | C32: =$C$15/$C$31 -> 0.1163291
A33: CEK TERHADAP MAKS. FILL RATIO | C33: =IF($C$32<=$C$8,"OK","NOT OK") -> OK
A34: Ukuran tray tertulis (W x H) | C34: =$C$30&" jalur "&$C$10&" x "&$C$7&" mm" -> 9 jalur 600 x 100 mm
A36: F. ALTERNATIF LEBAR TRAY STANDAR
A37: LEBAR TRAY (mm) | B37: LAYER 1 - JALUR | C37: LAYER 1 - FILL | D37: LAYER 2 - JALUR | E37: LAYER 2 - FILL | F37: LAYER 3 - JALUR | G37: LAYER 3 - FILL
A38: 100 | B38: =ROUNDUP(MAX($C$14*$C$6*(1+$C$5)/1,$C$15*(1+$C$5)/$C$8/$C$7/1)/$A38,0) -> 49 | C38: =$C$15/($A38*$C$7*1*B38) -> 0.12819942 | D38: =ROUNDUP(MAX($C$14*$C$6*(1+$C$5)/2,$C$15*(1+$C$5)/$C$8/$C$7/2)/$A38,0) -> 25 | E38: =$C$15/($A38*$C$7*2*D38) -> 0.12563543 | F38: =ROUNDUP(MAX($C$14*$C$6*(1+$C$5)/3,$C$15*(1+$C$5)/$C$8/$C$7/3)/$A38,0) -> 17 | G38: =$C$15/($A38*$C$7*3*F38) -> 0.12317199
A39: 150 | B39: =ROUNDUP(MAX($C$14*$C$6*(1+$C$5)/1,$C$15*(1+$C$5)/$C$8/$C$7/1)/$A39,0) -> 33 | C39: =$C$15/($A39*$C$7*1*B39) -> 0.12690448 | D39: =ROUNDUP(MAX($C$14*$C$6*(1+$C$5)/2,$C$15*(1+$C$5)/$C$8/$C$7/2)/$A39,0) -> 17 | E39: =$C$15/($A39*$C$7*2*D39) -> 0.12317199 | F39: =ROUNDUP(MAX($C$14*$C$6*(1+$C$5)/3,$C$15*(1+$C$5)/$C$8/$C$7/3)/$A39,0) -> 11 | G39: =$C$15/($A39*$C$7*3*F39) -> 0.12690448
A40: 200 | B40: =ROUNDUP(MAX($C$14*$C$6*(1+$C$5)/1,$C$15*(1+$C$5)/$C$8/$C$7/1)/$A40,0) -> 25 | C40: =$C$15/($A40*$C$7*1*B40) -> 0.12563543 | D40: =ROUNDUP(MAX($C$14*$C$6*(1+$C$5)/2,$C$15*(1+$C$5)/$C$8/$C$7/2)/$A40,0) -> 13 | E40: =$C$15/($A40*$C$7*2*D40) -> 0.1208033 | F40: =ROUNDUP(MAX($C$14*$C$6*(1+$C$5)/3,$C$15*(1+$C$5)/$C$8/$C$7/3)/$A40,0) -> 9 | G40: =$C$15/($A40*$C$7*3*F40) -> 0.1163291
A41: 300 | B41: =ROUNDUP(MAX($C$14*$C$6*(1+$C$5)/1,$C$15*(1+$C$5)/$C$8/$C$7/1)/$A41,0) -> 17 | C41: =$C$15/($A41*$C$7*1*B41) -> 0.12317199 | D41: =ROUNDUP(MAX($C$14*$C$6*(1+$C$5)/2,$C$15*(1+$C$5)/$C$8/$C$7/2)/$A41,0) -> 9 | E41: =$C$15/($A41*$C$7*2*D41) -> 0.1163291 | F41: =ROUNDUP(MAX($C$14*$C$6*(1+$C$5)/3,$C$15*(1+$C$5)/$C$8/$C$7/3)/$A41,0) -> 6 | G41: =$C$15/($A41*$C$7*3*F41) -> 0.1163291
A42: 400 | B42: =ROUNDUP(MAX($C$14*$C$6*(1+$C$5)/1,$C$15*(1+$C$5)/$C$8/$C$7/1)/$A42,0) -> 13 | C42: =$C$15/($A42*$C$7*1*B42) -> 0.1208033 | D42: =ROUNDUP(MAX($C$14*$C$6*(1+$C$5)/2,$C$15*(1+$C$5)/$C$8/$C$7/2)/$A42,0) -> 7 | E42: =$C$15/($A42*$C$7*2*D42) -> 0.11217449 | F42: =ROUNDUP(MAX($C$14*$C$6*(1+$C$5)/3,$C$15*(1+$C$5)/$C$8/$C$7/3)/$A42,0) -> 5 | G42: =$C$15/($A42*$C$7*3*F42) -> 0.10469619
A43: 500 | B43: =ROUNDUP(MAX($C$14*$C$6*(1+$C$5)/1,$C$15*(1+$C$5)/$C$8/$C$7/1)/$A43,0) -> 10 | C43: =$C$15/($A43*$C$7*1*B43) -> 0.12563543 | D43: =ROUNDUP(MAX($C$14*$C$6*(1+$C$5)/2,$C$15*(1+$C$5)/$C$8/$C$7/2)/$A43,0) -> 5 | E43: =$C$15/($A43*$C$7*2*D43) -> 0.12563543 | F43: =ROUNDUP(MAX($C$14*$C$6*(1+$C$5)/3,$C$15*(1+$C$5)/$C$8/$C$7/3)/$A43,0) -> 4 | G43: =$C$15/($A43*$C$7*3*F43) -> 0.10469619
A44: 600 | B44: =ROUNDUP(MAX($C$14*$C$6*(1+$C$5)/1,$C$15*(1+$C$5)/$C$8/$C$7/1)/$A44,0) -> 9 | C44: =$C$15/($A44*$C$7*1*B44) -> 0.1163291 | D44: =ROUNDUP(MAX($C$14*$C$6*(1+$C$5)/2,$C$15*(1+$C$5)/$C$8/$C$7/2)/$A44,0) -> 5 | E44: =$C$15/($A44*$C$7*2*D44) -> 0.10469619 | F44: =ROUNDUP(MAX($C$14*$C$6*(1+$C$5)/3,$C$15*(1+$C$5)/$C$8/$C$7/3)/$A44,0) -> 3 | G44: =$C$15/($A44*$C$7*3*F44) -> 0.1163291
A45: 800 | B45: =ROUNDUP(MAX($C$14*$C$6*(1+$C$5)/1,$C$15*(1+$C$5)/$C$8/$C$7/1)/$A45,0) -> 7 | C45: =$C$15/($A45*$C$7*1*B45) -> 0.11217449 | D45: =ROUNDUP(MAX($C$14*$C$6*(1+$C$5)/2,$C$15*(1+$C$5)/$C$8/$C$7/2)/$A45,0) -> 4 | E45: =$C$15/($A45*$C$7*2*D45) -> 0.098152681 | F45: =ROUNDUP(MAX($C$14*$C$6*(1+$C$5)/3,$C$15*(1+$C$5)/$C$8/$C$7/3)/$A45,0) -> 3 | G45: =$C$15/($A45*$C$7*3*F45) -> 0.087246828
A46: 1000 | B46: =ROUNDUP(MAX($C$14*$C$6*(1+$C$5)/1,$C$15*(1+$C$5)/$C$8/$C$7/1)/$A46,0) -> 5 | C46: =$C$15/($A46*$C$7*1*B46) -> 0.12563543 | D46: =ROUNDUP(MAX($C$14*$C$6*(1+$C$5)/2,$C$15*(1+$C$5)/$C$8/$C$7/2)/$A46,0) -> 3 | E46: =$C$15/($A46*$C$7*2*D46) -> 0.10469619 | F46: =ROUNDUP(MAX($C$14*$C$6*(1+$C$5)/3,$C$15*(1+$C$5)/$C$8/$C$7/3)/$A46,0) -> 2 | G46: =$C$15/($A46*$C$7*3*F46) -> 0.10469619
...
